<?xml version="1.0" ?>
<robot name="test_robot" xmlns:xacro="http://ros.org/wiki/xacro">

  <xacro:include filename="$(find choreonoid_ros_control_assembler_sample)/urdf/common.xacro"/>

  <link name="Root">
    <visual>
      <origin rpy="0 0 0" xyz="0 0.0 0"/>
      <geometry>
        <mesh filename="package://choreonoid_ros_control_assembler_sample/meshes/XL-430.stl"/>
      </geometry>
      <material name="black">
        <color rgba="0.2 0.2 0.2 1.0"/>
      </material>
    </visual>
  </link>
  
  <joint name="LINK_0" type="revolute">
    <axis xyz="0 0 1"/>
    <limit effort="1000.0" lower="-3.141592" upper="3.141592" velocity="0.5"/>
    <origin rpy="0 0 0" xyz="0 0 0.019"/>
    <parent link="Root"/>
    <child  link="LINK_0"/>
  </joint>

  <link name="LINK_0">
    <visual>
      <origin rpy="0 -1.57 0" xyz="0 0 -0.019"/>
      <geometry>
        <mesh filename="package://choreonoid_ros_control_assembler_sample/meshes/fr12-h102_p_m.stl"/>
      </geometry>
      <material name="white">
        <color rgba="0.8 0.8 0.8 1.0"/>
      </material>
    </visual>
  </link>

  <!-- Transmission -->
  <xacro:joint_position_trans_v0 name="LINK_0"/>

</robot>
